{"market": "0x32b09f6390252b37d674501527e709016d55581b2c1e544bd4b8167f5f732f4c", "asset_id": "90435811253665578014957380826505992530054077692143838383981805324273750424057", "timestamp": "1785130179174", "hash": "7d4fa12d9a7f7f027a2a749cec4d40361128b82a", "bids": [{"price": "0.01", "size": "52510"}, {"price": "0.02", "size": "1100005"}, {"price": "0.09", "size": "5000"}, {"price": "0.1", "size": "2000"}, {"price": "0.11", "size": "4546"}, {"price": "0.19", "size": "921.05"}, {"price": "0.21", "size": "50000"}, {"price": "0.22", "size": "14000"}, {"price": "0.23", "size": "1610.3"}, {"price": "0.24", "size": "29.16"}, {"price": "0.25", "size": "47.83"}, {"price": "0.45", "size": "50243.46"}, {"price": "0.46", "size": "20512"}, {"price": "0.47", "size": "1087.16"}, {"price": "0.48", "size": "667.37"}, {"price": "0.49", "size": "120114.52"}], "asks": [{"price": "0.99", "size": "1000010"}, {"price": "0.98", "size": "1250"}, {"price": "0.97", "size": "100000"}, {"price": "0.96", "size": "100000"}, {"price": "0.95", "size": "10000"}, {"price": "0.86", "size": "5.81"}, {"price": "0.85", "size": "50000"}, {"price": "0.84", "size": "13600"}, {"price": "0.83", "size": "47.83"}, {"price": "0.69", "size": "20000"}, {"price": "0.67", "size": "21.21"}, {"price": "0.56", "size": "12.94"}, {"price": "0.52", "size": "20030.94"}, {"price": "0.51", "size": "30000"}, {"price": "0.5", "size": "86200.09"}], "tick_size": "0.01", "event_type": "book", "last_trade_price": "0.490"}
{"market": "0x1fad72fae204143ff1c3035e99e7c0f65ea8d5cd9bd1070987bd1a3316f772be", "asset_id": "98022490269692409998126496127597032490334070080325855126491859374983463996227", "timestamp": "1785130175346", "hash": "ece635d4bd153b1e236e21a5f200e72d23947489", "bids": [{"price": "0.01", "size": "3830"}, {"price": "0.03", "size": "5"}, {"price": "0.04", "size": "25"}, {"price": "0.05", "size": "25"}, {"price": "0.09", "size": "1887"}, {"price": "0.1", "size": "5040"}, {"price": "0.11", "size": "472.72"}, {"price": "0.13", "size": "5"}, {"price": "0.14", "size": "8"}, {"price": "0.16", "size": "475"}, {"price": "0.19", "size": "400"}, {"price": "0.2", "size": "47.47"}, {"price": "0.22", "size": "5"}, {"price": "0.23", "size": "316.33"}, {"price": "0.24", "size": "1230"}, {"price": "0.25", "size": "10"}, {"price": "0.29", "size": "86.2"}, {"price": "0.3", "size": "15"}, {"price": "0.33", "size": "10"}, {"price": "0.35", "size": "2000"}, {"price": "0.36", "size": "1074.08"}, {"price": "0.37", "size": "208"}, {"price": "0.38", "size": "10"}, {"price": "0.39", "size": "35"}, {"price": "0.41", "size": "10"}, {"price": "0.42", "size": "16.66"}, {"price": "0.43", "size": "17.44"}, {"price": "0.44", "size": "26"}, {"price": "0.45", "size": "177.32"}, {"price": "0.46", "size": "26.49"}, {"price": "0.47", "size": "39.89"}, {"price": "0.48", "size": "93"}, {"price": "0.49", "size": "1062.97"}, {"price": "0.5", "size": "3699.91"}], "asks": [{"price": "0.99", "size": "2590"}, {"price": "0.97", "size": "25"}, {"price": "0.96", "size": "5"}, {"price": "0.95", "size": "1081.5"}, {"price": "0.93", "size": "405"}, {"price": "0.91", "size": "38.88"}, {"price": "0.81", "size": "1133.07"}, {"price": "0.8", "size": "47.47"}, {"price": "0.56", "size": "4.21"}, {"price": "0.54", "size": "521.86"}, {"price": "0.53", "size": "295"}, {"price": "0.52", "size": "2494.35"}, {"price": "0.51", "size": "5504.62"}], "tick_size": "0.01", "event_type": "book", "last_trade_price": "0.490"}
{"market": "0x50ddb9cd80d5c271664a2ebb7fcaed1d0a148d82c8e8d314d830f75a944c3dcc", "asset_id": "88275040060084773376557187972215267513049848642895776801789297917961077894224", "timestamp": "1785130157097", "hash": "4309a7cf755acc7a748be227c093a86a07d36a5c", "bids": [{"price": "0.01", "size": "1187.09"}, {"price": "0.06", "size": "990"}, {"price": "0.08", "size": "728.4"}, {"price": "0.1", "size": "2732.9"}, {"price": "0.11", "size": "1277.86"}, {"price": "0.12", "size": "383.35"}, {"price": "0.13", "size": "34.83"}, {"price": "0.26", "size": "13"}, {"price": "0.27", "size": "13"}, {"price": "0.34", "size": "43"}, {"price": "0.35", "size": "20"}, {"price": "0.48", "size": "2021"}, {"price": "0.49", "size": "482.15"}, {"price": "0.5", "size": "1601.02"}], "asks": [{"price": "0.99", "size": "1907.04"}, {"price": "0.95", "size": "480"}, {"price": "0.91", "size": "1133"}, {"price": "0.85", "size": "582"}, {"price": "0.84", "size": "47.47"}, {"price": "0.81", "size": "1575.24"}, {"price": "0.8", "size": "400"}, {"price": "0.78", "size": "479.4"}, {"price": "0.77", "size": "174"}, {"price": "0.76", "size": "1241"}, {"price": "0.75", "size": "80"}, {"price": "0.59", "size": "278.76"}, {"price": "0.58", "size": "167.78"}, {"price": "0.57", "size": "12.74"}, {"price": "0.56", "size": "52"}, {"price": "0.55", "size": "12"}, {"price": "0.54", "size": "8"}, {"price": "0.52", "size": "230.5"}, {"price": "0.51", "size": "819.92"}], "tick_size": "0.01", "event_type": "book", "last_trade_price": "0.500"}
{"market": "0x1fad72fae204143ff1c3035e99e7c0f65ea8d5cd9bd1070987bd1a3316f772be", "price_changes": [{"asset_id": "98022490269692409998126496127597032490334070080325855126491859374983463996227", "price": "0.36", "size": "1065.08", "side": "BUY", "hash": "eaccdc82b2b2806a013ea50fc5cf183dc02e9bc4", "best_bid": "0.5", "best_ask": "0.51"}, {"asset_id": "53831553061883006530739877284105938919721408776239639687877978808906551086026", "price": "0.64", "size": "1065.08", "side": "SELL", "hash": "bed613ca961bc7f9854481a63caaf193da519bf7", "best_bid": "0.49", "best_ask": "0.5"}], "timestamp": "1785130185252", "event_type": "price_change"}
{"market": "0x1fad72fae204143ff1c3035e99e7c0f65ea8d5cd9bd1070987bd1a3316f772be", "price_changes": [{"asset_id": "98022490269692409998126496127597032490334070080325855126491859374983463996227", "price": "0.24", "size": "1205", "side": "BUY", "hash": "eaccdc82b2b2806a013ea50fc5cf183dc02e9bc4", "best_bid": "0.5", "best_ask": "0.51"}, {"asset_id": "53831553061883006530739877284105938919721408776239639687877978808906551086026", "price": "0.76", "size": "1205", "side": "SELL", "hash": "bed613ca961bc7f9854481a63caaf193da519bf7", "best_bid": "0.49", "best_ask": "0.5"}], "timestamp": "1785130185252", "event_type": "price_change"}
{"market": "0x50ddb9cd80d5c271664a2ebb7fcaed1d0a148d82c8e8d314d830f75a944c3dcc", "price_changes": [{"asset_id": "94376205816022955542979635542279932967359915765455578534002478996104754801969", "price": "0.01", "size": "5", "side": "BUY", "hash": "4a54233dc954204d946a981124b11b004281da89", "best_bid": "0.49", "best_ask": "0.5"}, {"asset_id": "88275040060084773376557187972215267513049848642895776801789297917961077894224", "price": "0.99", "size": "5", "side": "SELL", "hash": "5aa42eedf1f3d40f5e3f6aa320765bae9dd65ba7", "best_bid": "0.5", "best_ask": "0.51"}], "timestamp": "1785130190009", "event_type": "price_change"}
{"market": "0x50ddb9cd80d5c271664a2ebb7fcaed1d0a148d82c8e8d314d830f75a944c3dcc", "price_changes": [{"asset_id": "94376205816022955542979635542279932967359915765455578534002478996104754801969", "price": "0.16", "size": "0", "side": "BUY", "hash": "6fd42b7c0e4849eb0c43ad39777b534bf001d27c", "best_bid": "0.49", "best_ask": "0.5"}, {"asset_id": "88275040060084773376557187972215267513049848642895776801789297917961077894224", "price": "0.84", "size": "0", "side": "SELL", "hash": "9bcb765920670a28b41065860d27ae263fd6009e", "best_bid": "0.5", "best_ask": "0.51"}], "timestamp": "1785130192144", "event_type": "price_change"}
{"market": "0x1fad72fae204143ff1c3035e99e7c0f65ea8d5cd9bd1070987bd1a3316f772be", "price_changes": [{"asset_id": "98022490269692409998126496127597032490334070080325855126491859374983463996227", "price": "0.2", "size": "0", "side": "BUY", "hash": "914110f9c04e414a20ff5efd848395e0aec52ceb", "best_bid": "0.5", "best_ask": "0.51"}, {"asset_id": "53831553061883006530739877284105938919721408776239639687877978808906551086026", "price": "0.8", "size": "0", "side": "SELL", "hash": "0adcfafaf898f0fb7ed7480e1aaea178e7153086", "best_bid": "0.49", "best_ask": "0.5"}], "timestamp": "1785130192144", "event_type": "price_change"}
{"market": "0x1fad72fae204143ff1c3035e99e7c0f65ea8d5cd9bd1070987bd1a3316f772be", "price_changes": [{"asset_id": "98022490269692409998126496127597032490334070080325855126491859374983463996227", "price": "0.26", "size": "47.47", "side": "BUY", "hash": "ef71f7cd3567c67e15368df18629c8f9ec68e93c", "best_bid": "0.5", "best_ask": "0.51"}, {"asset_id": "53831553061883006530739877284105938919721408776239639687877978808906551086026", "price": "0.74", "size": "47.47", "side": "SELL", "hash": "60fdb7f025823796dcf65cd268f8cc58ba45c6e9", "best_bid": "0.49", "best_ask": "0.5"}], "timestamp": "1785130192947", "event_type": "price_change"}
{"market": "0x1fad72fae204143ff1c3035e99e7c0f65ea8d5cd9bd1070987bd1a3316f772be", "price_changes": [{"asset_id": "98022490269692409998126496127597032490334070080325855126491859374983463996227", "price": "0.24", "size": "1230", "side": "BUY", "hash": "76017d94121826740b8270b6a6a5b91badc0b9f8", "best_bid": "0.5", "best_ask": "0.51"}, {"asset_id": "53831553061883006530739877284105938919721408776239639687877978808906551086026", "price": "0.76", "size": "1230", "side": "SELL", "hash": "9f73a65fbd2bdae573dfdbf1830ac8d2f8a54610", "best_bid": "0.49", "best_ask": "0.5"}], "timestamp": "1785130193393", "event_type": "price_change"}
{"market": "0x1fad72fae204143ff1c3035e99e7c0f65ea8d5cd9bd1070987bd1a3316f772be", "price_changes": [{"asset_id": "98022490269692409998126496127597032490334070080325855126491859374983463996227", "price": "0.36", "size": "1074.08", "side": "BUY", "hash": "47de84130752cd371174cdf17e6d96ccd5a41e6a", "best_bid": "0.5", "best_ask": "0.51"}, {"asset_id": "53831553061883006530739877284105938919721408776239639687877978808906551086026", "price": "0.64", "size": "1074.08", "side": "SELL", "hash": "25ce0495dc3c3588a4cf2e9118d96bffebf26b38", "best_bid": "0.49", "best_ask": "0.5"}], "timestamp": "1785130193394", "event_type": "price_change"}
{"market": "0x32b09f6390252b37d674501527e709016d55581b2c1e544bd4b8167f5f732f4c", "price_changes": [{"asset_id": "90435811253665578014957380826505992530054077692143838383981805324273750424057", "price": "0.23", "size": "1592", "side": "BUY", "hash": "7bf78a1e97a402e89f9c472372c625ca3e3d2cc4", "best_bid": "0.49", "best_ask": "0.5"}, {"asset_id": "92388629082681805622801622703528982922543286352927708208755887536971583436902", "price": "0.77", "size": "1592", "side": "SELL", "hash": "511c8c75a3cd30f89ce88f0fbd6adca84e1b1967", "best_bid": "0.5", "best_ask": "0.51"}], "timestamp": "1785130193475", "event_type": "price_change"}
{"market": "0x50ddb9cd80d5c271664a2ebb7fcaed1d0a148d82c8e8d314d830f75a944c3dcc", "price_changes": [{"asset_id": "94376205816022955542979635542279932967359915765455578534002478996104754801969", "price": "0.26", "size": "47.47", "side": "BUY", "hash": "56960c8baad11782b08c1a478cd23245889869a5", "best_bid": "0.49", "best_ask": "0.5"}, {"asset_id": "88275040060084773376557187972215267513049848642895776801789297917961077894224", "price": "0.74", "size": "47.47", "side": "SELL", "hash": "fa809644e986311f60df1be70dee25286447a588", "best_bid": "0.5", "best_ask": "0.51"}], "timestamp": "1785130194090", "event_type": "price_change"}
{"market": "0x1fad72fae204143ff1c3035e99e7c0f65ea8d5cd9bd1070987bd1a3316f772be", "price_changes": [{"asset_id": "98022490269692409998126496127597032490334070080325855126491859374983463996227", "price": "0.24", "size": "1205", "side": "BUY", "hash": "f0b439a56a3d1edb5cbe57dc3c4ce3120bcf4cae", "best_bid": "0.5", "best_ask": "0.51"}, {"asset_id": "53831553061883006530739877284105938919721408776239639687877978808906551086026", "price": "0.76", "size": "1205", "side": "SELL", "hash": "3cc57fdf66969818a2daec96337ba4d6a08667e5", "best_bid": "0.49", "best_ask": "0.5"}], "timestamp": "1785130197344", "event_type": "price_change"}
{"market": "0x1fad72fae204143ff1c3035e99e7c0f65ea8d5cd9bd1070987bd1a3316f772be", "price_changes": [{"asset_id": "98022490269692409998126496127597032490334070080325855126491859374983463996227", "price": "0.36", "size": "1065.08", "side": "BUY", "hash": "f0b439a56a3d1edb5cbe57dc3c4ce3120bcf4cae", "best_bid": "0.5", "best_ask": "0.51"}, {"asset_id": "53831553061883006530739877284105938919721408776239639687877978808906551086026", "price": "0.64", "size": "1065.08", "side": "SELL", "hash": "3cc57fdf66969818a2daec96337ba4d6a08667e5", "best_bid": "0.49", "best_ask": "0.5"}], "timestamp": "1785130197344", "event_type": "price_change"}
{"market": "0x50ddb9cd80d5c271664a2ebb7fcaed1d0a148d82c8e8d314d830f75a944c3dcc", "price_changes": [{"asset_id": "88275040060084773376557187972215267513049848642895776801789297917961077894224", "price": "0.11", "size": "5.86", "side": "BUY", "hash": "aab6c0bb1bc56620574315137ecb67cb25bc2870", "best_bid": "0.5", "best_ask": "0.51"}, {"asset_id": "94376205816022955542979635542279932967359915765455578534002478996104754801969", "price": "0.89", "size": "5.86", "side": "SELL", "hash": "27d501bfdc398ec89c64fde7512298402e491e4a", "best_bid": "0.49", "best_ask": "0.5"}], "timestamp": "1785130198001", "event_type": "price_change"}
{"market": "0x50ddb9cd80d5c271664a2ebb7fcaed1d0a148d82c8e8d314d830f75a944c3dcc", "price_changes": [{"asset_id": "94376205816022955542979635542279932967359915765455578534002478996104754801969", "price": "0.2", "size": "0", "side": "BUY", "hash": "2fc4a014839ccd5eb97ab31684eca6bb71f6dbd0", "best_bid": "0.49", "best_ask": "0.5"}, {"asset_id": "88275040060084773376557187972215267513049848642895776801789297917961077894224", "price": "0.8", "size": "0", "side": "SELL", "hash": "8818db285423481ea2b6e710aa0f0ab946e86f82", "best_bid": "0.5", "best_ask": "0.51"}], "timestamp": "1785130198690", "event_type": "price_change"}
{"market": "0x50ddb9cd80d5c271664a2ebb7fcaed1d0a148d82c8e8d314d830f75a944c3dcc", "price_changes": [{"asset_id": "94376205816022955542979635542279932967359915765455578534002478996104754801969", "price": "0.23", "size": "348", "side": "BUY", "hash": "0d61e270a6e86925d662ed01113a820c019ec587", "best_bid": "0.49", "best_ask": "0.5"}, {"asset_id": "88275040060084773376557187972215267513049848642895776801789297917961077894224", "price": "0.77", "size": "348", "side": "SELL", "hash": "943f7d6e4dfd78de5454ac11f79320e6d46fba73", "best_bid": "0.5", "best_ask": "0.51"}], "timestamp": "1785130198691", "event_type": "price_change"}
{"market": "0x50ddb9cd80d5c271664a2ebb7fcaed1d0a148d82c8e8d314d830f75a944c3dcc", "price_changes": [{"asset_id": "94376205816022955542979635542279932967359915765455578534002478996104754801969", "price": "0.27", "size": "75", "side": "BUY", "hash": "4ff11fb4e087a84047f2207a62406cb3189edc58", "best_bid": "0.49", "best_ask": "0.5"}, {"asset_id": "88275040060084773376557187972215267513049848642895776801789297917961077894224", "price": "0.73", "size": "75", "side": "SELL", "hash": "d28b4391aa116aef3e6dc8376ac6bc6fba07020f", "best_bid": "0.5", "best_ask": "0.51"}], "timestamp": "1785130198693", "event_type": "price_change"}
{"market": "0x50ddb9cd80d5c271664a2ebb7fcaed1d0a148d82c8e8d314d830f75a944c3dcc", "price_changes": [{"asset_id": "94376205816022955542979635542279932967359915765455578534002478996104754801969", "price": "0.25", "size": "160", "side": "BUY", "hash": "7a86af2cfc7b0f48f6da417b450d0e871b4cecda", "best_bid": "0.49", "best_ask": "0.5"}, {"asset_id": "88275040060084773376557187972215267513049848642895776801789297917961077894224", "price": "0.75", "size": "160", "side": "SELL", "hash": "89925261275ebd0b3b86e8b851af5776db201272", "best_bid": "0.5", "best_ask": "0.51"}], "timestamp": "1785130198694", "event_type": "price_change"}
{"market": "0x50ddb9cd80d5c271664a2ebb7fcaed1d0a148d82c8e8d314d830f75a944c3dcc", "price_changes": [{"asset_id": "94376205816022955542979635542279932967359915765455578534002478996104754801969", "price": "0.01", "size": "1907.04", "side": "BUY", "hash": "b8e9c685a0fc3d869c613031db1cc8df00ceabef", "best_bid": "0.49", "best_ask": "0.5"}, {"asset_id": "88275040060084773376557187972215267513049848642895776801789297917961077894224", "price": "0.99", "size": "1907.04", "side": "SELL", "hash": "822cbb0508dca76b57ace545883df8c17f79ed2a", "best_bid": "0.5", "best_ask": "0.51"}], "timestamp": "1785130198899", "event_type": "price_change"}
{"market": "0x50ddb9cd80d5c271664a2ebb7fcaed1d0a148d82c8e8d314d830f75a944c3dcc", "price_changes": [{"asset_id": "94376205816022955542979635542279932967359915765455578534002478996104754801969", "price": "0.23", "size": "522", "side": "BUY", "hash": "c22840de194ca10a49f550c19b86a4a3bc2cbd1e", "best_bid": "0.49", "best_ask": "0.5"}, {"asset_id": "88275040060084773376557187972215267513049848642895776801789297917961077894224", "price": "0.77", "size": "522", "side": "SELL", "hash": "ee757d8094c21d145534f20c18e556e6f857d2d5", "best_bid": "0.5", "best_ask": "0.51"}], "timestamp": "1785130199205", "event_type": "price_change"}
{"market": "0x50ddb9cd80d5c271664a2ebb7fcaed1d0a148d82c8e8d314d830f75a944c3dcc", "price_changes": [{"asset_id": "94376205816022955542979635542279932967359915765455578534002478996104754801969", "price": "0.25", "size": "240", "side": "BUY", "hash": "e008c62c3e3a69c8c078f9e712e2ec420afa2c41", "best_bid": "0.49", "best_ask": "0.5"}, {"asset_id": "88275040060084773376557187972215267513049848642895776801789297917961077894224", "price": "0.75", "size": "240", "side": "SELL", "hash": "2edafb3d4d476cd5f059c75cb3f2447ab25ba6f4", "best_bid": "0.5", "best_ask": "0.51"}], "timestamp": "1785130199206", "event_type": "price_change"}
{"market": "0x50ddb9cd80d5c271664a2ebb7fcaed1d0a148d82c8e8d314d830f75a944c3dcc", "price_changes": [{"asset_id": "94376205816022955542979635542279932967359915765455578534002478996104754801969", "price": "0.27", "size": "150", "side": "BUY", "hash": "b2b620d43b0689bb4e7172393c1021c7ec8574b9", "best_bid": "0.49", "best_ask": "0.5"}, {"asset_id": "88275040060084773376557187972215267513049848642895776801789297917961077894224", "price": "0.73", "size": "150", "side": "SELL", "hash": "e9a3a55ca3cda47f76f6610eea9e8bed53f66295", "best_bid": "0.5", "best_ask": "0.51"}], "timestamp": "1785130199207", "event_type": "price_change"}
{"market": "0x32b09f6390252b37d674501527e709016d55581b2c1e544bd4b8167f5f732f4c", "price_changes": [{"asset_id": "90435811253665578014957380826505992530054077692143838383981805324273750424057", "price": "0.19", "size": "2673.68", "side": "BUY", "hash": "bafb88a95278d06e88b4dd3b3205087052f47e86", "best_bid": "0.49", "best_ask": "0.5"}, {"asset_id": "92388629082681805622801622703528982922543286352927708208755887536971583436902", "price": "0.81", "size": "2673.68", "side": "SELL", "hash": "4c46d921bbe60378da33a2ea136162d84a9a0630", "best_bid": "0.5", "best_ask": "0.51"}], "timestamp": "1785130199588", "event_type": "price_change"}
{"market": "0x1fad72fae204143ff1c3035e99e7c0f65ea8d5cd9bd1070987bd1a3316f772be", "price_changes": [{"asset_id": "98022490269692409998126496127597032490334070080325855126491859374983463996227", "price": "0.25", "size": "1510", "side": "BUY", "hash": "e08d1e66ecd2ac3fb7d002d0a79e7433ad076a36", "best_bid": "0.5", "best_ask": "0.51"}, {"asset_id": "53831553061883006530739877284105938919721408776239639687877978808906551086026", "price": "0.75", "size": "1510", "side": "SELL", "hash": "228d3c51cbbe83af86b1ddab2f90327ee094b1d1", "best_bid": "0.49", "best_ask": "0.5"}], "timestamp": "1785130199590", "event_type": "price_change"}
{"market": "0x1fad72fae204143ff1c3035e99e7c0f65ea8d5cd9bd1070987bd1a3316f772be", "price_changes": [{"asset_id": "98022490269692409998126496127597032490334070080325855126491859374983463996227", "price": "0.24", "size": "0", "side": "BUY", "hash": "de24926dddf69b94e9dc0c26eeb532dedd25013f", "best_bid": "0.5", "best_ask": "0.51"}, {"asset_id": "53831553061883006530739877284105938919721408776239639687877978808906551086026", "price": "0.76", "size": "0", "side": "SELL", "hash": "ffcf7e3faa94dd78a1852738fcbec3fc052def10", "best_bid": "0.49", "best_ask": "0.5"}], "timestamp": "1785130202237", "event_type": "price_change"}
{"market": "0x1fad72fae204143ff1c3035e99e7c0f65ea8d5cd9bd1070987bd1a3316f772be", "price_changes": [{"asset_id": "98022490269692409998126496127597032490334070080325855126491859374983463996227", "price": "0.26", "size": "1159.47", "side": "BUY", "hash": "6788e2b4f001bc7fed9861d6f47e9f90964b0b6a", "best_bid": "0.5", "best_ask": "0.51"}, {"asset_id": "53831553061883006530739877284105938919721408776239639687877978808906551086026", "price": "0.74", "size": "1159.47", "side": "SELL", "hash": "d237f30791bb0d6348e9dcf12c5005443c27dc6e", "best_bid": "0.49", "best_ask": "0.5"}], "timestamp": "1785130202271", "event_type": "price_change"}
{"market": "0x50ddb9cd80d5c271664a2ebb7fcaed1d0a148d82c8e8d314d830f75a944c3dcc", "price_changes": [{"asset_id": "94376205816022955542979635542279932967359915765455578534002478996104754801969", "price": "0.23", "size": "348", "side": "BUY", "hash": "bb25085b4d325a4de9b5bb9cfd30cfaadc3465c8", "best_bid": "0.49", "best_ask": "0.5"}, {"asset_id": "88275040060084773376557187972215267513049848642895776801789297917961077894224", "price": "0.77", "size": "348", "side": "SELL", "hash": "d6404c56da9c6c0d53568b8e2c6b0bf06af64a16", "best_bid": "0.5", "best_ask": "0.51"}], "timestamp": "1785130203272", "event_type": "price_change"}
{"market": "0x50ddb9cd80d5c271664a2ebb7fcaed1d0a148d82c8e8d314d830f75a944c3dcc", "price_changes": [{"asset_id": "94376205816022955542979635542279932967359915765455578534002478996104754801969", "price": "0.25", "size": "160", "side": "BUY", "hash": "bb25085b4d325a4de9b5bb9cfd30cfaadc3465c8", "best_bid": "0.49", "best_ask": "0.5"}, {"asset_id": "88275040060084773376557187972215267513049848642895776801789297917961077894224", "price": "0.75", "size": "160", "side": "SELL", "hash": "d6404c56da9c6c0d53568b8e2c6b0bf06af64a16", "best_bid": "0.5", "best_ask": "0.51"}], "timestamp": "1785130203272", "event_type": "price_change"}
{"market": "0x50ddb9cd80d5c271664a2ebb7fcaed1d0a148d82c8e8d314d830f75a944c3dcc", "price_changes": [{"asset_id": "94376205816022955542979635542279932967359915765455578534002478996104754801969", "price": "0.27", "size": "75", "side": "BUY", "hash": "bb25085b4d325a4de9b5bb9cfd30cfaadc3465c8", "best_bid": "0.49", "best_ask": "0.5"}, {"asset_id": "88275040060084773376557187972215267513049848642895776801789297917961077894224", "price": "0.73", "size": "75", "side": "SELL", "hash": "d6404c56da9c6c0d53568b8e2c6b0bf06af64a16", "best_bid": "0.5", "best_ask": "0.51"}], "timestamp": "1785130203272", "event_type": "price_change"}
{"market": "0x32b09f6390252b37d674501527e709016d55581b2c1e544bd4b8167f5f732f4c", "price_changes": [{"asset_id": "90435811253665578014957380826505992530054077692143838383981805324273750424057", "price": "0.01", "size": "50010", "side": "BUY", "hash": "6203db927f329e8909fd19f04e05e0c1b9458134", "best_bid": "0.49", "best_ask": "0.5"}, {"asset_id": "92388629082681805622801622703528982922543286352927708208755887536971583436902", "price": "0.99", "size": "50010", "side": "SELL", "hash": "167d45227c385e716d3ed8b656788bc08313ad50", "best_bid": "0.5", "best_ask": "0.51"}], "timestamp": "1785130205000", "event_type": "price_change"}
